2022-12-24 03:14:09,099:ERROR:telebot:Infinity polling exception
2022-12-24 03:15:27,331:ERROR:telebot:Infinity polling exception
2022-12-24 03:16:45,465:ERROR:telebot:Infinity polling exception
2022-12-24 03:21:17,788:ERROR:TeleBot:Infinity polling: polling exited
2022-12-24 03:21:17,789:ERROR:TeleBot:Break infinity polling
2022-12-24 11:21:48,298 (__init__.py:970 MainThread) ERROR - TeleBot: "Infinity polling exception: HTTPSConnectionPool(host='api.telegram.org', port=443): Max retries exceeded with url: /bot5861111194:AAH3nf8lnAzrVtTsNmD--Y7aT7L27DVV2Cs/getMe (Caused by ConnectTimeoutError(<urllib3.connection.HTTPSConnection object at 0x7fdd5d4b0c40>, 'Connection to api.telegram.org timed out. (connect timeout=15)'))"
2022-12-24 11:21:48,298:ERROR:TeleBot:Infinity polling exception: HTTPSConnectionPool(host='api.telegram.org', port=443): Max retries exceeded with url: /bot5861111194:AAH3nf8lnAzrVtTsNmD--Y7aT7L27DVV2Cs/getMe (Caused by ConnectTimeoutError(<urllib3.connection.HTTPSConnection object at 0x7fdd5d4b0c40>, 'Connection to api.telegram.org timed out. (connect timeout=15)'))
2022-12-24 11:26:06,882 (__init__.py:974 MainThread) ERROR - TeleBot: "Exception traceback:
Traceback (most recent call last):
  File "/home/amin/Desktop/pythonProjects/telebot/venv/lib/python3.8/site-packages/urllib3/connection.py", line 174, in _new_conn
    conn = connection.create_connection(
  File "/home/amin/Desktop/pythonProjects/telebot/venv/lib/python3.8/site-packages/urllib3/util/connection.py", line 95, in create_connection
    raise err
  File "/home/amin/Desktop/pythonProjects/telebot/venv/lib/python3.8/site-packages/urllib3/util/connection.py", line 85, in create_connection
    sock.connect(sa)
socket.timeout: timed out

During handling of the above exception, another exception occurred:

Traceback (most recent call last):
  File "/home/amin/Desktop/pythonProjects/telebot/venv/lib/python3.8/site-packages/urllib3/connectionpool.py", line 703, in urlopen
    httplib_response = self._make_request(
  File "/home/amin/Desktop/pythonProjects/telebot/venv/lib/python3.8/site-packages/urllib3/connectionpool.py", line 386, in _make_request
    self._validate_conn(conn)
  File "/home/amin/Desktop/pythonProjects/telebot/venv/lib/python3.8/site-packages/urllib3/connectionpool.py", line 1042, in _validate_conn
    conn.connect()
  File "/home/amin/Desktop/pythonProjects/telebot/venv/lib/python3.8/site-packages/urllib3/connection.py", line 358, in connect
    self.sock = conn = self._new_conn()
  File "/home/amin/Desktop/pythonProjects/telebot/venv/lib/python3.8/site-packages/urllib3/connection.py", line 179, in _new_conn
    raise ConnectTimeoutError(
urllib3.exceptions.ConnectTimeoutError: (<urllib3.connection.HTTPSConnection object at 0x7f0d49888c70>, 'Connection to api.telegram.org timed out. (connect timeout=15)')

During handling of the above exception, another exception occurred:

Traceback (most recent call last):
  File "/home/amin/Desktop/pythonProjects/telebot/venv/lib/python3.8/site-packages/requests/adapters.py", line 489, in send
    resp = conn.urlopen(
  File "/home/amin/Desktop/pythonProjects/telebot/venv/lib/python3.8/site-packages/urllib3/connectionpool.py", line 787, in urlopen
    retries = retries.increment(
  File "/home/amin/Desktop/pythonProjects/telebot/venv/lib/python3.8/site-packages/urllib3/util/retry.py", line 592, in increment
    raise MaxRetryError(_pool, url, error or ResponseError(cause))
urllib3.exceptions.MaxRetryError: HTTPSConnectionPool(host='api.telegram.org', port=443): Max retries exceeded with url: /bot5861111194:AAH3nf8lnAzrVtTsNmD--Y7aT7L27DVV2Cs/getMe (Caused by ConnectTimeoutError(<urllib3.connection.HTTPSConnection object at 0x7f0d49888c70>, 'Connection to api.telegram.org timed out. (connect timeout=15)'))

During handling of the above exception, another exception occurred:

Traceback (most recent call last):
  File "/home/amin/Desktop/pythonProjects/telebot/venv/lib/python3.8/site-packages/telebot/__init__.py", line 965, in infinity_polling
    self.polling(non_stop=True, timeout=timeout, long_polling_timeout=long_polling_timeout,
  File "/home/amin/Desktop/pythonProjects/telebot/venv/lib/python3.8/site-packages/telebot/__init__.py", line 1052, in polling
    logger.info('Starting your bot with username: [@%s]', self.user.username)
  File "/home/amin/Desktop/pythonProjects/telebot/venv/lib/python3.8/site-packages/telebot/__init__.py", line 279, in user
    self._user = self.get_me()
  File "/home/amin/Desktop/pythonProjects/telebot/venv/lib/python3.8/site-packages/telebot/__init__.py", line 1248, in get_me
    result = apihelper.get_me(self.token)
  File "/home/amin/Desktop/pythonProjects/telebot/venv/lib/python3.8/site-packages/telebot/apihelper.py", line 196, in get_me
    return _make_request(token, method_url)
  File "/home/amin/Desktop/pythonProjects/telebot/venv/lib/python3.8/site-packages/telebot/apihelper.py", line 156, in _make_request
    result = _get_req_session().request(
  File "/home/amin/Desktop/pythonProjects/telebot/venv/lib/python3.8/site-packages/requests/sessions.py", line 587, in request
    resp = self.send(prep, **send_kwargs)
  File "/home/amin/Desktop/pythonProjects/telebot/venv/lib/python3.8/site-packages/requests/sessions.py", line 701, in send
    r = adapter.send(request, **kwargs)
  File "/home/amin/Desktop/pythonProjects/telebot/venv/lib/python3.8/site-packages/requests/adapters.py", line 553, in send
    raise ConnectTimeout(e, request=request)
requests.exceptions.ConnectTimeout: HTTPSConnectionPool(host='api.telegram.org', port=443): Max retries exceeded with url: /bot5861111194:AAH3nf8lnAzrVtTsNmD--Y7aT7L27DVV2Cs/getMe (Caused by ConnectTimeoutError(<urllib3.connection.HTTPSConnection object at 0x7f0d49888c70>, 'Connection to api.telegram.org timed out. (connect timeout=15)'))
"
2022-12-24 11:26:06,882:ERROR:TeleBot:Exception traceback:
Traceback (most recent call last):
  File "/home/amin/Desktop/pythonProjects/telebot/venv/lib/python3.8/site-packages/urllib3/connection.py", line 174, in _new_conn
    conn = connection.create_connection(
  File "/home/amin/Desktop/pythonProjects/telebot/venv/lib/python3.8/site-packages/urllib3/util/connection.py", line 95, in create_connection
    raise err
  File "/home/amin/Desktop/pythonProjects/telebot/venv/lib/python3.8/site-packages/urllib3/util/connection.py", line 85, in create_connection
    sock.connect(sa)
socket.timeout: timed out

During handling of the above exception, another exception occurred:

Traceback (most recent call last):
  File "/home/amin/Desktop/pythonProjects/telebot/venv/lib/python3.8/site-packages/urllib3/connectionpool.py", line 703, in urlopen
    httplib_response = self._make_request(
  File "/home/amin/Desktop/pythonProjects/telebot/venv/lib/python3.8/site-packages/urllib3/connectionpool.py", line 386, in _make_request
    self._validate_conn(conn)
  File "/home/amin/Desktop/pythonProjects/telebot/venv/lib/python3.8/site-packages/urllib3/connectionpool.py", line 1042, in _validate_conn
    conn.connect()
  File "/home/amin/Desktop/pythonProjects/telebot/venv/lib/python3.8/site-packages/urllib3/connection.py", line 358, in connect
    self.sock = conn = self._new_conn()
  File "/home/amin/Desktop/pythonProjects/telebot/venv/lib/python3.8/site-packages/urllib3/connection.py", line 179, in _new_conn
    raise ConnectTimeoutError(
urllib3.exceptions.ConnectTimeoutError: (<urllib3.connection.HTTPSConnection object at 0x7f0d49888c70>, 'Connection to api.telegram.org timed out. (connect timeout=15)')

During handling of the above exception, another exception occurred:

Traceback (most recent call last):
  File "/home/amin/Desktop/pythonProjects/telebot/venv/lib/python3.8/site-packages/requests/adapters.py", line 489, in send
    resp = conn.urlopen(
  File "/home/amin/Desktop/pythonProjects/telebot/venv/lib/python3.8/site-packages/urllib3/connectionpool.py", line 787, in urlopen
    retries = retries.increment(
  File "/home/amin/Desktop/pythonProjects/telebot/venv/lib/python3.8/site-packages/urllib3/util/retry.py", line 592, in increment
    raise MaxRetryError(_pool, url, error or ResponseError(cause))
urllib3.exceptions.MaxRetryError: HTTPSConnectionPool(host='api.telegram.org', port=443): Max retries exceeded with url: /bot5861111194:AAH3nf8lnAzrVtTsNmD--Y7aT7L27DVV2Cs/getMe (Caused by ConnectTimeoutError(<urllib3.connection.HTTPSConnection object at 0x7f0d49888c70>, 'Connection to api.telegram.org timed out. (connect timeout=15)'))

During handling of the above exception, another exception occurred:

Traceback (most recent call last):
  File "/home/amin/Desktop/pythonProjects/telebot/venv/lib/python3.8/site-packages/telebot/__init__.py", line 965, in infinity_polling
    self.polling(non_stop=True, timeout=timeout, long_polling_timeout=long_polling_timeout,
  File "/home/amin/Desktop/pythonProjects/telebot/venv/lib/python3.8/site-packages/telebot/__init__.py", line 1052, in polling
    logger.info('Starting your bot with username: [@%s]', self.user.username)
  File "/home/amin/Desktop/pythonProjects/telebot/venv/lib/python3.8/site-packages/telebot/__init__.py", line 279, in user
    self._user = self.get_me()
  File "/home/amin/Desktop/pythonProjects/telebot/venv/lib/python3.8/site-packages/telebot/__init__.py", line 1248, in get_me
    result = apihelper.get_me(self.token)
  File "/home/amin/Desktop/pythonProjects/telebot/venv/lib/python3.8/site-packages/telebot/apihelper.py", line 196, in get_me
    return _make_request(token, method_url)
  File "/home/amin/Desktop/pythonProjects/telebot/venv/lib/python3.8/site-packages/telebot/apihelper.py", line 156, in _make_request
    result = _get_req_session().request(
  File "/home/amin/Desktop/pythonProjects/telebot/venv/lib/python3.8/site-packages/requests/sessions.py", line 587, in request
    resp = self.send(prep, **send_kwargs)
  File "/home/amin/Desktop/pythonProjects/telebot/venv/lib/python3.8/site-packages/requests/sessions.py", line 701, in send
    r = adapter.send(request, **kwargs)
  File "/home/amin/Desktop/pythonProjects/telebot/venv/lib/python3.8/site-packages/requests/adapters.py", line 553, in send
    raise ConnectTimeout(e, request=request)
requests.exceptions.ConnectTimeout: HTTPSConnectionPool(host='api.telegram.org', port=443): Max retries exceeded with url: /bot5861111194:AAH3nf8lnAzrVtTsNmD--Y7aT7L27DVV2Cs/getMe (Caused by ConnectTimeoutError(<urllib3.connection.HTTPSConnection object at 0x7f0d49888c70>, 'Connection to api.telegram.org timed out. (connect timeout=15)'))

